Workbook

Sheet Audit Log
A1: Audit ID | B1: Date | C1: Area | D1: Audit type | E1: Original audit ID | F1: Auditor | G1: Checks done | H1: Checks passed | I1: Main finding | J1: Pass rate | K1: Result | L1: Month | M1: Confirmation status
A2: A001 | B2: 46209 | C2: Picking | D2: Routine | F2: Auditor A | G2: 12 | H2: 11 | J2: =H2/G2 | K2: =IF(J2>=0.9,"Pass","Fail") | L2: =TEXT(B2,"yyyy-mm") | M2: =IF(AND(D2="Routine",K2="Fail"),IF(COUNTIFS($E$2:$E$72,A2,$K$2:$K$72,"Pass")>0,"Closed",IF(COUNTIFS($E$2:$E$72,A2)>0,"Re-failed","Awaiting confirmation")),"")
A3: A002 | B3: 46210 | C3: Goods In | D3: Routine | F3: Auditor A | G3: 20 | H3: 19 | J3: =H3/G3 | K3: =IF(J3>=0.9,"Pass","Fail") | L3: =TEXT(B3,"yyyy-mm") | M3: =IF(AND(D3="Routine",K3="Fail"),IF(COUNTIFS($E$2:$E$72,A3,$K$2:$K$72,"Pass")>0,"Closed",IF(COUNTIFS($E$2:$E$72,A3)>0,"Re-failed","Awaiting confirmation")),"")
A4: A003 | B4: 46210 | C4: Hazardous Storage | D4: Routine | F4: Auditor B | G4: 10 | H4: 10 | J4: =H4/G4 | K4: =IF(J4>=0.9,"Pass","Fail") | L4: =TEXT(B4,"yyyy-mm") | M4: =IF(AND(D4="Routine",K4="Fail"),IF(COUNTIFS($E$2:$E$72,A4,$K$2:$K$72,"Pass")>0,"Closed",IF(COUNTIFS($E$2:$E$72,A4)>0,"Re-failed","Awaiting confirmation")),"")
A5: A004 | B5: 46212 | C5: Despatch | D5: Routine | F5: Auditor A | G5: 10 | H5: 10 | J5: =H5/G5 | K5: =IF(J5>=0.9,"Pass","Fail") | L5: =TEXT(B5,"yyyy-mm") | M5: =IF(AND(D5="Routine",K5="Fail"),IF(COUNTIFS($E$2:$E$72,A5,$K$2:$K$72,"Pass")>0,"Closed",IF(COUNTIFS($E$2:$E$72,A5)>0,"Re-failed","Awaiting confirmation")),"")
A6: A005 | B6: 46216 | C6: Picking | D6: Routine | F6: Auditor A | G6: 15 | H6: 14 | J6: =H6/G6 | K6: =IF(J6>=0.9,"Pass","Fail") | L6: =TEXT(B6,"yyyy-mm") | M6: =IF(AND(D6="Routine",K6="Fail"),IF(COUNTIFS($E$2:$E$72,A6,$K$2:$K$72,"Pass")>0,"Closed",IF(COUNTIFS($E$2:$E$72,A6)>0,"Re-failed","Awaiting confirmation")),"")
A7: A006 | B7: 46217 | C7: Goods In | D7: Routine | F7: Auditor B | G7: 10 | H7: 9 | J7: =H7/G7 | K7: =IF(J7>=0.9,"Pass","Fail") | L7: =TEXT(B7,"yyyy-mm") | M7: =IF(AND(D7="Routine",K7="Fail"),IF(COUNTIFS($E$2:$E$72,A7,$K$2:$K$72,"Pass")>0,"Closed",IF(COUNTIFS($E$2:$E$72,A7)>0,"Re-failed","Awaiting confirmation")),"")
A8: A007 | B8: 46219 | C8: Hazardous Storage | D8: Routine | F8: Auditor B | G8: 15 | H8: 13 | I8: Log not signed | J8: =H8/G8 | K8: =IF(J8>=0.9,"Pass","Fail") | L8: =TEXT(B8,"yyyy-mm") | M8: =IF(AND(D8="Routine",K8="Fail"),IF(COUNTIFS($E$2:$E$72,A8,$K$2:$K$72,"Pass")>0,"Closed",IF(COUNTIFS($E$2:$E$72,A8)>0,"Re-failed","Awaiting confirmation")),"")
A9: A008 | B9: 46220 | C9: Despatch | D9: Routine | F9: Auditor A | G9: 12 | H9: 11 | J9: =H9/G9 | K9: =IF(J9>=0.9,"Pass","Fail") | L9: =TEXT(B9,"yyyy-mm") | M9: =IF(AND(D9="Routine",K9="Fail"),IF(COUNTIFS($E$2:$E$72,A9,$K$2:$K$72,"Pass")>0,"Closed",IF(COUNTIFS($E$2:$E$72,A9)>0,"Re-failed","Awaiting confirmation")),"")
A10: A009 | B10: 46220 | C10: Returns | D10: Routine | F10: Auditor B | G10: 12 | H10: 11 | J10: =H10/G10 | K10: =IF(J10>=0.9,"Pass","Fail") | L10: =TEXT(B10,"yyyy-mm") | M10: =IF(AND(D10="Routine",K10="Fail"),IF(COUNTIFS($E$2:$E$72,A10,$K$2:$K$72,"Pass")>0,"Closed",IF(COUNTIFS($E$2:$E$72,A10)>0,"Re-failed","Awaiting confirmation")),"")
A11: A010 | B11: 46223 | C11: Despatch | D11: Routine | F11: Auditor B | G11: 10 | H11: 9 | J11: =H11/G11 | K11: =IF(J11>=0.9,"Pass","Fail") | L11: =TEXT(B11,"yyyy-mm") | M11: =IF(AND(D11="Routine",K11="Fail"),IF(COUNTIFS($E$2:$E$72,A11,$K$2:$K$72,"Pass")>0,"Closed",IF(COUNTIFS($E$2:$E$72,A11)>0,"Re-failed","Awaiting confirmation")),"")
A12: A011 | B12: 46224 | C12: Goods In | D12: Routine | F12: Auditor A | G12: 12 | H12: 12 | J12: =H12/G12 | K12: =IF(J12>=0.9,"Pass","Fail") | L12: =TEXT(B12,"yyyy-mm") | M12: =IF(AND(D12="Routine",K12="Fail"),IF(COUNTIFS($E$2:$E$72,A12,$K$2:$K$72,"Pass")>0,"Closed",IF(COUNTIFS($E$2:$E$72,A12)>0,"Re-failed","Awaiting confirmation")),"")
A13: A012 | B13: 46225 | C13: Returns | D13: Routine | F13: Auditor A | G13: 12 | H13: 11 | J13: =H13/G13 | K13: =IF(J13>=0.9,"Pass","Fail") | L13: =TEXT(B13,"yyyy-mm") | M13: =IF(AND(D13="Routine",K13="Fail"),IF(COUNTIFS($E$2:$E$72,A13,$K$2:$K$72,"Pass")>0,"Closed",IF(COUNTIFS($E$2:$E$72,A13)>0,"Re-failed","Awaiting confirmation")),"")
A14: A013 | B14: 46227 | C14: Picking | D14: Routine | F14: Auditor B | G14: 20 | H14: 19 | J14: =H14/G14 | K14: =IF(J14>=0.9,"Pass","Fail") | L14: =TEXT(B14,"yyyy-mm") | M14: =IF(AND(D14="Routine",K14="Fail"),IF(COUNTIFS($E$2:$E$72,A14,$K$2:$K$72,"Pass")>0,"Closed",IF(COUNTIFS($E$2:$E$72,A14)>0,"Re-failed","Awaiting confirmation")),"")
A15: A014 | B15: 46227 | C15: Hazardous Storage | D15: Routine | F15: Auditor B | G15: 15 | H15: 14 | J15: =H15/G15 | K15: =IF(J15>=0.9,"Pass","Fail") | L15: =TEXT(B15,"yyyy-mm") | M15: =IF(AND(D15="Routine",K15="Fail"),IF(COUNTIFS($E$2:$E$72,A15,$K$2:$K$72,"Pass")>0,"Closed",IF(COUNTIFS($E$2:$E$72,A15)>0,"Re-failed","Awaiting confirmation")),"")
A16: A015 | B16: 46230 | C16: Despatch | D16: Routine | F16: Auditor B | G16: 10 | H16: 9 | J16: =H16/G16 | K16: =IF(J16>=0.9,"Pass","Fail") | L16: =TEXT(B16,"yyyy-mm") | M16: =IF(AND(D16="Routine",K16="Fail"),IF(COUNTIFS($E$2:$E$72,A16,$K$2:$K$72,"Pass")>0,"Closed",IF(COUNTIFS($E$2:$E$72,A16)>0,"Re-failed","Awaiting confirmation")),"")
A17: A016 | B17: 46233 | C17: Returns | D17: Routine | F17: Auditor B | G17: 15 | H17: 13 | I17: Late processing | J17: =H17/G17 | K17: =IF(J17>=0.9,"Pass","Fail") | L17: =TEXT(B17,"yyyy-mm") | M17: =IF(AND(D17="Routine",K17="Fail"),IF(COUNTIFS($E$2:$E$72,A17,$K$2:$K$72,"Pass")>0,"Closed",IF(COUNTIFS($E$2:$E$72,A17)>0,"Re-failed","Awaiting confirmation")),"")
A18: A017 | B18: 46233 | C18: Hazardous Storage | D18: Routine | F18: Auditor A | G18: 15 | H18: 13 | I18: Spill kit not checked | J18: =H18/G18 | K18: =IF(J18>=0.9,"Pass","Fail") | L18: =TEXT(B18,"yyyy-mm") | M18: =IF(AND(D18="Routine",K18="Fail"),IF(COUNTIFS($E$2:$E$72,A18,$K$2:$K$72,"Pass")>0,"Closed",IF(COUNTIFS($E$2:$E$72,A18)>0,"Re-failed","Awaiting confirmation")),"")
A19: A018 | B19: 46234 | C19: Goods In | D19: Routine | F19: Auditor A | G19: 20 | H19: 18 | J19: =H19/G19 | K19: =IF(J19>=0.9,"Pass","Fail") | L19: =TEXT(B19,"yyyy-mm") | M19: =IF(AND(D19="Routine",K19="Fail"),IF(COUNTIFS($E$2:$E$72,A19,$K$2:$K$72,"Pass")>0,"Closed",IF(COUNTIFS($E$2:$E$72,A19)>0,"Re-failed","Awaiting confirmation")),"")
A20: A019 | B20: 46238 | C20: Hazardous Storage | D20: Routine | F20: Auditor B | G20: 12 | H20: 12 | J20: =H20/G20 | K20: =IF(J20>=0.9,"Pass","Fail") | L20: =TEXT(B20,"yyyy-mm") | M20: =IF(AND(D20="Routine",K20="Fail"),IF(COUNTIFS($E$2:$E$72,A20,$K$2:$K$72,"Pass")>0,"Closed",IF(COUNTIFS($E$2:$E$72,A20)>0,"Re-failed","Awaiting confirmation")),"")
A21: A020 | B21: 46239 | C21: Returns | D21: Routine | F21: Auditor A | G21: 20 | H21: 16 | I21: Reason code missing | J21: =H21/G21 | K21: =IF(J21>=0.9,"Pass","Fail") | L21: =TEXT(B21,"yyyy-mm") | M21: =IF(AND(D21="Routine",K21="Fail"),IF(COUNTIFS($E$2:$E$72,A21,$K$2:$K$72,"Pass")>0,"Closed",IF(COUNTIFS($E$2:$E$72,A21)>0,"Re-failed","Awaiting confirmation")),"")
A22: A021 | B22: 46240 | C22: Goods In | D22: Routine | F22: Auditor A | G22: 10 | H22: 10 | J22: =H22/G22 | K22: =IF(J22>=0.9,"Pass","Fail") | L22: =TEXT(B22,"yyyy-mm") | M22: =IF(AND(D22="Routine",K22="Fail"),IF(COUNTIFS($E$2:$E$72,A22,$K$2:$K$72,"Pass")>0,"Closed",IF(COUNTIFS($E$2:$E$72,A22)>0,"Re-failed","Awaiting confirmation")),"")
A23: A022 | B23: 46240 | C23: Picking | D23: Routine | F23: Auditor A | G23: 10 | H23: 10 | J23: =H23/G23 | K23: =IF(J23>=0.9,"Pass","Fail") | L23: =TEXT(B23,"yyyy-mm") | M23: =IF(AND(D23="Routine",K23="Fail"),IF(COUNTIFS($E$2:$E$72,A23,$K$2:$K$72,"Pass")>0,"Closed",IF(COUNTIFS($E$2:$E$72,A23)>0,"Re-failed","Awaiting confirmation")),"")
A24: A023 | B24: 46241 | C24: Despatch | D24: Routine | F24: Auditor B | G24: 15 | H24: 15 | J24: =H24/G24 | K24: =IF(J24>=0.9,"Pass","Fail") | L24: =TEXT(B24,"yyyy-mm") | M24: =IF(AND(D24="Routine",K24="Fail"),IF(COUNTIFS($E$2:$E$72,A24,$K$2:$K$72,"Pass")>0,"Closed",IF(COUNTIFS($E$2:$E$72,A24)>0,"Re-failed","Awaiting confirmation")),"")
A25: A024 | B25: 46241 | C25: Hazardous Storage | D25: Confirmation | E25: A017 | F25: Auditor A | G25: 15 | H25: 15 | J25: =H25/G25 | K25: =IF(J25>=0.9,"Pass","Fail") | L25: =TEXT(B25,"yyyy-mm") | M25: =IF(AND(D25="Routine",K25="Fail"),IF(COUNTIFS($E$2:$E$72,A25,$K$2:$K$72,"Pass")>0,"Closed",IF(COUNTIFS($E$2:$E$72,A25)>0,"Re-failed","Awaiting confirmation")),"")
A26: A025 | B26: 46244 | C26: Hazardous Storage | D26: Routine | F26: Auditor A | G26: 20 | H26: 20 | J26: =H26/G26 | K26: =IF(J26>=0.9,"Pass","Fail") | L26: =TEXT(B26,"yyyy-mm") | M26: =IF(AND(D26="Routine",K26="Fail"),IF(COUNTIFS($E$2:$E$72,A26,$K$2:$K$72,"Pass")>0,"Closed",IF(COUNTIFS($E$2:$E$72,A26)>0,"Re-failed","Awaiting confirmation")),"")
A27: A026 | B27: 46246 | C27: Picking | D27: Routine | F27: Auditor A | G27: 10 | H27: 10 | J27: =H27/G27 | K27: =IF(J27>=0.9,"Pass","Fail") | L27: =TEXT(B27,"yyyy-mm") | M27: =IF(AND(D27="Routine",K27="Fail"),IF(COUNTIFS($E$2:$E$72,A27,$K$2:$K$72,"Pass")>0,"Closed",IF(COUNTIFS($E$2:$E$72,A27)>0,"Re-failed","Awaiting confirmation")),"")
A28: A027 | B28: 46246 | C28: Despatch | D28: Routine | F28: Auditor A | G28: 15 | H28: 15 | J28: =H28/G28 | K28: =IF(J28>=0.9,"Pass","Fail") | L28: =TEXT(B28,"yyyy-mm") | M28: =IF(AND(D28="Routine",K28="Fail"),IF(COUNTIFS($E$2:$E$72,A28,$K$2:$K$72,"Pass")>0,"Closed",IF(COUNTIFS($E$2:$E$72,A28)>0,"Re-failed","Awaiting confirmation")),"")
A29: A028 | B29: 46247 | C29: Returns | D29: Confirmation | E29: A016 | F29: Auditor B | G29: 15 | H29: 14 | J29: =H29/G29 | K29: =IF(J29>=0.9,"Pass","Fail") | L29: =TEXT(B29,"yyyy-mm") | M29: =IF(AND(D29="Routine",K29="Fail"),IF(COUNTIFS($E$2:$E$72,A29,$K$2:$K$72,"Pass")>0,"Closed",IF(COUNTIFS($E$2:$E$72,A29)>0,"Re-failed","Awaiting confirmation")),"")
A30: A029 | B30: 46248 | C30: Returns | D30: Routine | F30: Auditor B | G30: 20 | H30: 17 | I30: Late processing | J30: =H30/G30 | K30: =IF(J30>=0.9,"Pass","Fail") | L30: =TEXT(B30,"yyyy-mm") | M30: =IF(AND(D30="Routine",K30="Fail"),IF(COUNTIFS($E$2:$E$72,A30,$K$2:$K$72,"Pass")>0,"Closed",IF(COUNTIFS($E$2:$E$72,A30)>0,"Re-failed","Awaiting confirmation")),"")
A31: A030 | B31: 46251 | C31: Picking | D31: Routine | F31: Auditor A | G31: 15 | H31: 14 | J31: =H31/G31 | K31: =IF(J31>=0.9,"Pass","Fail") | L31: =TEXT(B31,"yyyy-mm") | M31: =IF(AND(D31="Routine",K31="Fail"),IF(COUNTIFS($E$2:$E$72,A31,$K$2:$K$72,"Pass")>0,"Closed",IF(COUNTIFS($E$2:$E$72,A31)>0,"Re-failed","Awaiting confirmation")),"")
A32: A031 | B32: 46252 | C32: Returns | D32: Routine | F32: Auditor A | G32: 20 | H32: 17 | I32: Item not quarantined | J32: =H32/G32 | K32: =IF(J32>=0.9,"Pass","Fail") | L32: =TEXT(B32,"yyyy-mm") | M32: =IF(AND(D32="Routine",K32="Fail"),IF(COUNTIFS($E$2:$E$72,A32,$K$2:$K$72,"Pass")>0,"Closed",IF(COUNTIFS($E$2:$E$72,A32)>0,"Re-failed","Awaiting confirmation")),"")
A33: A032 | B33: 46252 | C33: Returns | D33: Confirmation | E33: A020 | F33: Auditor A | G33: 20 | H33: 19 | J33: =H33/G33 | K33: =IF(J33>=0.9,"Pass","Fail") | L33: =TEXT(B33,"yyyy-mm") | M33: =IF(AND(D33="Routine",K33="Fail"),IF(COUNTIFS($E$2:$E$72,A33,$K$2:$K$72,"Pass")>0,"Closed",IF(COUNTIFS($E$2:$E$72,A33)>0,"Re-failed","Awaiting confirmation")),"")
A34: A033 | B34: 46253 | C34: Hazardous Storage | D34: Routine | F34: Auditor B | G34: 15 | H34: 14 | J34: =H34/G34 | K34: =IF(J34>=0.9,"Pass","Fail") | L34: =TEXT(B34,"yyyy-mm") | M34: =IF(AND(D34="Routine",K34="Fail"),IF(COUNTIFS($E$2:$E$72,A34,$K$2:$K$72,"Pass")>0,"Closed",IF(COUNTIFS($E$2:$E$72,A34)>0,"Re-failed","Awaiting confirmation")),"")
A35: A034 | B35: 46255 | C35: Despatch | D35: Routine | F35: Auditor A | G35: 12 | H35: 10 | I35: Load not secured | J35: =H35/G35 | K35: =IF(J35>=0.9,"Pass","Fail") | L35: =TEXT(B35,"yyyy-mm") | M35: =IF(AND(D35="Routine",K35="Fail"),IF(COUNTIFS($E$2:$E$72,A35,$K$2:$K$72,"Pass")>0,"Closed",IF(COUNTIFS($E$2:$E$72,A35)>0,"Re-failed","Awaiting confirmation")),"")
A36: A035 | B36: 46257 | C36: Returns | D36: Confirmation | E36: A029 | F36: Auditor B | G36: 20 | H36: 18 | J36: =H36/G36 | K36: =IF(J36>=0.9,"Pass","Fail") | L36: =TEXT(B36,"yyyy-mm") | M36: =IF(AND(D36="Routine",K36="Fail"),IF(COUNTIFS($E$2:$E$72,A36,$K$2:$K$72,"Pass")>0,"Closed",IF(COUNTIFS($E$2:$E$72,A36)>0,"Re-failed","Awaiting confirmation")),"")
A37: A036 | B37: 46258 | C37: Hazardous Storage | D37: Routine | F37: Auditor B | G37: 15 | H37: 15 | J37: =H37/G37 | K37: =IF(J37>=0.9,"Pass","Fail") | L37: =TEXT(B37,"yyyy-mm") | M37: =IF(AND(D37="Routine",K37="Fail"),IF(COUNTIFS($E$2:$E$72,A37,$K$2:$K$72,"Pass")>0,"Closed",IF(COUNTIFS($E$2:$E$72,A37)>0,"Re-failed","Awaiting confirmation")),"")
A38: A037 | B38: 46260 | C38: Despatch | D38: Routine | F38: Auditor A | G38: 15 | H38: 13 | I38: Load not secured | J38: =H38/G38 | K38: =IF(J38>=0.9,"Pass","Fail") | L38: =TEXT(B38,"yyyy-mm") | M38: =IF(AND(D38="Routine",K38="Fail"),IF(COUNTIFS($E$2:$E$72,A38,$K$2:$K$72,"Pass")>0,"Closed",IF(COUNTIFS($E$2:$E$72,A38)>0,"Re-failed","Awaiting confirmation")),"")
A39: A038 | B39: 46261 | C39: Picking | D39: Routine | F39: Auditor A | G39: 15 | H39: 14 | J39: =H39/G39 | K39: =IF(J39>=0.9,"Pass","Fail") | L39: =TEXT(B39,"yyyy-mm") | M39: =IF(AND(D39="Routine",K39="Fail"),IF(COUNTIFS($E$2:$E$72,A39,$K$2:$K$72,"Pass")>0,"Closed",IF(COUNTIFS($E$2:$E$72,A39)>0,"Re-failed","Awaiting confirmation")),"")
A40: A039 | B40: 46262 | C40: Returns | D40: Routine | F40: Auditor A | G40: 15 | H40: 13 | I40: Item not quarantined | J40: =H40/G40 | K40: =IF(J40>=0.9,"Pass","Fail") | L40: =TEXT(B40,"yyyy-mm") | M40: =IF(AND(D40="Routine",K40="Fail"),IF(COUNTIFS($E$2:$E$72,A40,$K$2:$K$72,"Pass")>0,"Closed",IF(COUNTIFS($E$2:$E$72,A40)>0,"Re-failed","Awaiting confirmation")),"")
...

Sheet Summary
A1: Audit summary (fictional sample data)
A2: Pass mark | B2: 0.9 | C2: (change in Audit Log formulas if the standard differs)
A4: By area | B4: Audits | C4: Passed | D4: Failed | E4: Fail rate | F4: Average pass rate
A5: Goods In | B5: =COUNTIFS('Audit Log'!$C$2:$C$72,A5,'Audit Log'!$D$2:$D$72,"Routine") | C5: =COUNTIFS('Audit Log'!$C$2:$C$72,A5,'Audit Log'!$D$2:$D$72,"Routine",'Audit Log'!$K$2:$K$72,"Pass") | D5: =B5-C5 | E5: =IFERROR(D5/B5,0) | F5: =IFERROR(AVERAGEIFS('Audit Log'!$J$2:$J$72,'Audit Log'!$C$2:$C$72,A5,'Audit Log'!$D$2:$D$72,"Routine"),0)
A6: Picking | B6: =COUNTIFS('Audit Log'!$C$2:$C$72,A6,'Audit Log'!$D$2:$D$72,"Routine") | C6: =COUNTIFS('Audit Log'!$C$2:$C$72,A6,'Audit Log'!$D$2:$D$72,"Routine",'Audit Log'!$K$2:$K$72,"Pass") | D6: =B6-C6 | E6: =IFERROR(D6/B6,0) | F6: =IFERROR(AVERAGEIFS('Audit Log'!$J$2:$J$72,'Audit Log'!$C$2:$C$72,A6,'Audit Log'!$D$2:$D$72,"Routine"),0)
A7: Despatch | B7: =COUNTIFS('Audit Log'!$C$2:$C$72,A7,'Audit Log'!$D$2:$D$72,"Routine") | C7: =COUNTIFS('Audit Log'!$C$2:$C$72,A7,'Audit Log'!$D$2:$D$72,"Routine",'Audit Log'!$K$2:$K$72,"Pass") | D7: =B7-C7 | E7: =IFERROR(D7/B7,0) | F7: =IFERROR(AVERAGEIFS('Audit Log'!$J$2:$J$72,'Audit Log'!$C$2:$C$72,A7,'Audit Log'!$D$2:$D$72,"Routine"),0)
A8: Returns | B8: =COUNTIFS('Audit Log'!$C$2:$C$72,A8,'Audit Log'!$D$2:$D$72,"Routine") | C8: =COUNTIFS('Audit Log'!$C$2:$C$72,A8,'Audit Log'!$D$2:$D$72,"Routine",'Audit Log'!$K$2:$K$72,"Pass") | D8: =B8-C8 | E8: =IFERROR(D8/B8,0) | F8: =IFERROR(AVERAGEIFS('Audit Log'!$J$2:$J$72,'Audit Log'!$C$2:$C$72,A8,'Audit Log'!$D$2:$D$72,"Routine"),0)
A9: Hazardous Storage | B9: =COUNTIFS('Audit Log'!$C$2:$C$72,A9,'Audit Log'!$D$2:$D$72,"Routine") | C9: =COUNTIFS('Audit Log'!$C$2:$C$72,A9,'Audit Log'!$D$2:$D$72,"Routine",'Audit Log'!$K$2:$K$72,"Pass") | D9: =B9-C9 | E9: =IFERROR(D9/B9,0) | F9: =IFERROR(AVERAGEIFS('Audit Log'!$J$2:$J$72,'Audit Log'!$C$2:$C$72,A9,'Audit Log'!$D$2:$D$72,"Routine"),0)
A10: Total | B10: =SUM(B5:B9) | C10: =SUM(C5:C9) | D10: =SUM(D5:D9) | E10: =IFERROR(D10/B10,0) | F10: =IFERROR(AVERAGEIFS('Audit Log'!$J$2:$J$72,'Audit Log'!$D$2:$D$72,"Routine"),0)
A12: By month (routine audits)
A13: Month | B13: Audits | C13: Failed | D13: Fail rate | E13: Average pass rate
A14: 2026-07 | B14: =COUNTIFS('Audit Log'!$L$2:$L$72,A14,'Audit Log'!$D$2:$D$72,"Routine") | C14: =COUNTIFS('Audit Log'!$L$2:$L$72,A14,'Audit Log'!$D$2:$D$72,"Routine",'Audit Log'!$K$2:$K$72,"Fail") | D14: =IFERROR(C14/B14,0) | E14: =IFERROR(AVERAGEIFS('Audit Log'!$J$2:$J$72,'Audit Log'!$L$2:$L$72,A14,'Audit Log'!$D$2:$D$72,"Routine"),0)
A15: 2026-08 | B15: =COUNTIFS('Audit Log'!$L$2:$L$72,A15,'Audit Log'!$D$2:$D$72,"Routine") | C15: =COUNTIFS('Audit Log'!$L$2:$L$72,A15,'Audit Log'!$D$2:$D$72,"Routine",'Audit Log'!$K$2:$K$72,"Fail") | D15: =IFERROR(C15/B15,0) | E15: =IFERROR(AVERAGEIFS('Audit Log'!$J$2:$J$72,'Audit Log'!$L$2:$L$72,A15,'Audit Log'!$D$2:$D$72,"Routine"),0)
A16: 2026-09 | B16: =COUNTIFS('Audit Log'!$L$2:$L$72,A16,'Audit Log'!$D$2:$D$72,"Routine") | C16: =COUNTIFS('Audit Log'!$L$2:$L$72,A16,'Audit Log'!$D$2:$D$72,"Routine",'Audit Log'!$K$2:$K$72,"Fail") | D16: =IFERROR(C16/B16,0) | E16: =IFERROR(AVERAGEIFS('Audit Log'!$J$2:$J$72,'Audit Log'!$L$2:$L$72,A16,'Audit Log'!$D$2:$D$72,"Routine"),0)
A17: 2026-10 | B17: =COUNTIFS('Audit Log'!$L$2:$L$72,A17,'Audit Log'!$D$2:$D$72,"Routine") | C17: =COUNTIFS('Audit Log'!$L$2:$L$72,A17,'Audit Log'!$D$2:$D$72,"Routine",'Audit Log'!$K$2:$K$72,"Fail") | D17: =IFERROR(C17/B17,0) | E17: =IFERROR(AVERAGEIFS('Audit Log'!$J$2:$J$72,'Audit Log'!$L$2:$L$72,A17,'Audit Log'!$D$2:$D$72,"Routine"),0)
A19: Confirmation audits on failed routine audits
A20: Closed (confirmation passed) | B20: =COUNTIFS('Audit Log'!$M$2:$M$72,"Closed")
A21: Re-failed on confirmation | B21: =COUNTIFS('Audit Log'!$M$2:$M$72,"Re-failed")
A22: Awaiting confirmation | B22: =COUNTIFS('Audit Log'!$M$2:$M$72,"Awaiting confirmation")
